# 第 10 章 - 编程实践 - 抛出自定义错误

## 10.1 错误的本质

略

## 10.2 在 JavaScript 中抛出错误

任何类型的对象都可以作为错误抛出，然而，Error 对象是最常用的。如果愿意，你可以抛出任何类型的数据，但是由于浏览器对其实现的不统一，**如果要抛出错误，请始终抛出 Error 对象**。

```javascript
throw new Error('Something bad happened');

// 不好的写法
throw 'message';
throw 123;
throw true;
throw {key: 'value'};
```

如果没有通过 try-catch 语句捕获，抛出任何值都将引发一个错误。

## 10.3 抛出错误的好处

略

## 10.4 何时抛出错误

由于 JavaScript 没有类型和参数检查，大量的开发者错误地假设他们自己应该实现每个函数的类型检查。这种做法并不实际，并且会对脚本的整体性能造成影响。

```javascript
// 不好的写法，检查了太多错误
function addClass(element, className) {
  if (!element || typeof element.className !== 'string') {
    throw new Error('addClass(): First argument must be a DOM element.');
  }

  if (typeof className !== 'string') {
    throw new Error('addClass(): Second argument must be a string');
  }

  element.className += ' ' + className;
}
```

在上例中，最有可能引发错误的是给函数传递一个 null 引用值。如果第二个参数是 null 或者一个数字或者一个布尔值是不会抛出错误的，因为 JavaScript 会将其强制转换为字符串。那意味着导致 DOM 元素的显示不符合期望，**但这并不至于提高到严重错误的程度**。所以，我只会检查 DOM 元素。

```javascript
// 好的写法
function addClass(element, className) {
  if (!element || typeof element.className !== 'string') {
    throw new Error('addClass(): First argument must be a DOM element.');
  }

  element.className += '' + className;
}
```

如果一个函数只被已知的实体调用，错误检查很可能没有必要（这个案例是私有函数）；如果不能提前确定函数会被调用的所有地方，你很可能需要一些错误检查。**抛出错误最佳的地方是在工具函数中**，如 addClass 函数，它是通用脚本环境中的一部分，会在很多地方使用。更准确的案例是 JavaScript 类库（jQuery，Underscore ..）

针对已知条件引发的错误，所有的 JavaScript 类库都应该从它们的公共接口里抛出错误。当你做错事的时候通知你是它们的责任，因为你不可能进入库代码中去调试错误的原因。**函数调用栈应该在进入库代码接口时就终止**，不应该更深了。

这里有一些关于抛出错误很好的经验法则。

- 一旦修复了一个很难调试的错误，尝试增加一两个自定义错误。当再次发生错误时，这将有助于容易地解决问题。

- 如果正在编写代码，思考一下: "我希望「某些事情」不会发生，如果发生，我的代码会一团糟糕。" 这时，如果「某些事情」发生，就抛出一个错误。

- 如果正在编写的代码别人也会使用，思考一下他们使用的方式，在特定的情况下抛出错误。


## 10.5 try-catch 语句

JavaScript 提供了 try-catch 语句，它能在浏览器处理抛出的错误之前来解析它。可能引发错误的代码放在 try 块，处理错误的代码放在 catch 块。

```javascript
try {
  somethingThatMightCauseAnError();
} catch (ex) {
  handleError(ex);
}
```

当在 try 块中发生了一个错误时，程序立即停止执行，然后跳到 catch 块，并传入一个错误对象。

当然，我们还可以增加一个 finally 块。**finally 块中的代码不管是否有错误发生，最后都会被执行**。

```javascript
try {
  somethingThatMightCauseAnError();
} catch (ex) {
  handleError(ex);
} finally {
  continueDoingOtherStuff();
}
```

在某些情况下，finally 块工作起来有点复杂（微妙）。例如，如果 try 块中包含了一个 return 语句，实际上它必须等到 finally 块中的代码执行后才能返回。

```javascript
function fn() {
  try {
    return 1;
  } catch (ex) {
    // ...
  } finally {
    return 2;
  }
}

let tmp = fn();
console.log(tmp);  // 2
```

```javascript
function fn() {
  try {
    return 2;
  } catch (ex) {
    // ...
  } finally {
    console.log(1);
  }
}

let tmp = fn();
console.log(tmp);
// 控制台分别输出 1 2
```

关于 try-catch 的使用有一个经典案例 「[一次由于开启 Safari 无痕浏览 引发的艰难“捉虫”事件](http://www.cnblogs.com/zichi/p/4961677.html)」

## 10.6 错误类型

ECMA-262 规范指出了 7 种类型错误。当不同错误条件发生时，这些类型在 JavaScript 引擎中都有用到，当然我们也可以手动创建它们。

- Error（所有错误的基本类型，实际上引擎从来不会抛出该类型的错误）
- EvalError
- RangeError
- ReferenceError
- SyntaxError
- TypeError
- URIError
